Internal Server Error: /contract/
Traceback (most recent call last):
  File "F:\P12\venv\lib\site-packages\django\utils\dateparse.py", line 114, in parse_datetime
    return datetime.datetime.fromisoformat(value)
ValueError: day is out of range for month

During handling of the above exception, another exception occurred:

Traceback (most recent call last):
  File "F:\P12\venv\lib\site-packages\django\db\models\fields\__init__.py", line 1485, in to_python
    parsed = parse_datetime(value)
  File "F:\P12\venv\lib\site-packages\django\utils\dateparse.py", line 129, in parse_datetime
    return datetime.datetime(**kw, tzinfo=tzinfo)
ValueError: day is out of range for month

During handling of the above exception, another exception occurred:

Traceback (most recent call last):
  File "F:\P12\venv\lib\site-packages\django\core\handlers\exception.py", line 55, in inner
    response = get_response(request)
  File "F:\P12\venv\lib\site-packages\django\core\handlers\base.py", line 197, in _get_response
    response = wrapped_callback(request, *callback_args, **callback_kwargs)
  File "F:\P12\venv\lib\site-packages\django\views\decorators\csrf.py", line 54, in wrapped_view
    return view_func(*args, **kwargs)
  File "F:\P12\venv\lib\site-packages\rest_framework\viewsets.py", line 125, in view
    return self.dispatch(request, *args, **kwargs)
  File "F:\P12\venv\lib\site-packages\rest_framework\views.py", line 509, in dispatch
    response = self.handle_exception(exc)
  File "F:\P12\venv\lib\site-packages\rest_framework\views.py", line 469, in handle_exception
    self.raise_uncaught_exception(exc)
  File "F:\P12\venv\lib\site-packages\rest_framework\views.py", line 480, in raise_uncaught_exception
    raise exc
  File "F:\P12\venv\lib\site-packages\rest_framework\views.py", line 497, in dispatch
    self.initial(request, *args, **kwargs)
  File "F:\P12\venv\lib\site-packages\rest_framework\views.py", line 415, in initial
    self.check_permissions(request)
  File "F:\P12\venv\lib\site-packages\rest_framework\views.py", line 332, in check_permissions
    if not permission.has_permission(request, self):
  File "F:\P12\venv\lib\site-packages\rest_framework\permissions.py", line 229, in has_permission
    queryset = self._queryset(view)
  File "F:\P12\venv\lib\site-packages\rest_framework\permissions.py", line 212, in _queryset
    queryset = view.get_queryset()
  File "F:\P12\api\views.py", line 148, in get_queryset
    queryset = queryset.filter(
  File "F:\P12\venv\lib\site-packages\django\db\models\query.py", line 1071, in filter
    return self._filter_or_exclude(False, args, kwargs)
  File "F:\P12\venv\lib\site-packages\django\db\models\query.py", line 1089, in _filter_or_exclude
    clone._filter_or_exclude_inplace(negate, args, kwargs)
  File "F:\P12\venv\lib\site-packages\django\db\models\query.py", line 1096, in _filter_or_exclude_inplace
    self._query.add_q(Q(*args, **kwargs))
  File "F:\P12\venv\lib\site-packages\django\db\models\sql\query.py", line 1502, in add_q
    clause, _ = self._add_q(q_object, self.used_aliases)
  File "F:\P12\venv\lib\site-packages\django\db\models\sql\query.py", line 1532, in _add_q
    child_clause, needed_inner = self.build_filter(
  File "F:\P12\venv\lib\site-packages\django\db\models\sql\query.py", line 1448, in build_filter
    condition = self.build_lookup(lookups, col, value)
  File "F:\P12\venv\lib\site-packages\django\db\models\sql\query.py", line 1273, in build_lookup
    lookup = lookup_class(lhs, rhs)
  File "F:\P12\venv\lib\site-packages\django\db\models\lookups.py", line 27, in __init__
    self.rhs = self.get_prep_lookup()
  File "F:\P12\venv\lib\site-packages\django\db\models\lookups.py", line 85, in get_prep_lookup
    return self.lhs.output_field.get_prep_value(self.rhs)
  File "F:\P12\venv\lib\site-packages\django\db\models\fields\__init__.py", line 1524, in get_prep_value
    value = super().get_prep_value(value)
  File "F:\P12\venv\lib\site-packages\django\db\models\fields\__init__.py", line 1403, in get_prep_value
    return self.to_python(value)
  File "F:\P12\venv\lib\site-packages\django\db\models\fields\__init__.py", line 1489, in to_python
    raise exceptions.ValidationError(
django.core.exceptions.ValidationError: ['Åg2022-05-55 00:00:00Åh value has the correct format (YYYY-MM-DD HH:MM[:ss[.uuuuuu]][TZ]) but it is an invalid date/time.']
"GET /contract/?date=2022-05-55%2000:00:00 HTTP/1.1" 500 174751
Bad Request: /event/
"POST /event/ HTTP/1.1" 400 128
Bad Request: /event/
"POST /event/ HTTP/1.1" 400 128
Forbidden: /event/11/
"PUT /event/11/ HTTP/1.1" 403 63
Bad Request: /event/11/
"PUT /event/11/ HTTP/1.1" 400 42
Forbidden: /event/11/
"DELETE /event/11/ HTTP/1.1" 403 63
Forbidden: /client/
"POST /client/ HTTP/1.1" 403 63
Bad Request: /client/
"POST /client/ HTTP/1.1" 400 52
Forbidden: /client/1/
"PATCH /client/1/ HTTP/1.1" 403 63
Bad Request: /token/
"POST /token/ HTTP/1.1" 400 37
Forbidden: /client/1/
"GET /client/1/ HTTP/1.1" 403 63
Forbidden: /event/10/
"PATCH /event/10/ HTTP/1.1" 403 63
Forbidden: /event/9/
"DELETE /event/9/ HTTP/1.1" 403 63
Unauthorized: /client/
"GET /client/ HTTP/1.1" 401 183
Forbidden: /client/1/
"GET /client/1/ HTTP/1.1" 403 63
Forbidden: /client/1/
"PUT /client/1/ HTTP/1.1" 403 63
